2023-06-14 04:11:38.730807: I tensorflow/core/util/port.cc:110] oneDNN custom operations are on. You may see slightly different numerical results due to floating-point round-off errors from different computation orders. To turn them off, set the environment variable `TF_ENABLE_ONEDNN_OPTS=0`.
2023-06-14 04:11:43.790288: I tensorflow/core/platform/cpu_feature_guard.cc:182] This TensorFlow binary is optimized to use available CPU instructions in performance-critical operations.
To enable the following instructions: AVX2 AVX512F AVX512_VNNI FMA, in other operations, rebuild TensorFlow with the appropriate compiler flags.
2023-06-14 04:13:25.868732: W tensorflow/compiler/tf2tensorrt/utils/py_utils.cc:38] TF-TRT Warning: Could not find TensorRT

API status:
        Using Python: 3.11.3 (main, Apr 19 2023, 23:54:32) [GCC 11.2.0]
        Using tensorflow: 2.12.0
        Using keras: 2.12.0
        Available GPUs: [PhysicalDevice(name='/physical_device:GPU:0', 
device_type='GPU')]


Found 83520 images belonging to 4 classes.
Found 20880 images belonging to 4 classes.
2023-06-14 04:17:38.507397: I tensorflow/core/common_runtime/gpu/gpu_device.cc:1635] Created device /job:localhost/replica:0/task:0/device:GPU:0 with 43422 MB memory:  -> device: 0, name: NVIDIA A40, pci bus id: 0000:65:00.0, compute capability: 8.6
Model: "model"
_________________________________________________________________
 Layer (type)                Output Shape              Param #   
=================================================================
 input_2 (InputLayer)        [(None, 224, 224, 3)]     0         
                                                                 
 tf.__operators__.getitem (S  (None, 224, 224, 3)      0         
 licingOpLambda)                                                 
                                                                 
 tf.nn.bias_add (TFOpLambda)  (None, 224, 224, 3)      0         
                                                                 
 vgg16 (Functional)          (None, None, None, 512)   14714688  
                                                                 
 global_average_pooling2d (G  (None, 512)              0         
 lobalAveragePooling2D)                                          
                                                                 
 dense (Dense)               (None, 512)               262656    
                                                                 
 batch_normalization (BatchN  (None, 512)              2048      
 ormalization)                                                   
                                                                 
 dropout (Dropout)           (None, 512)               0         
                                                                 
 activation (Activation)     (None, 512)               0         
                                                                 
 dense_1 (Dense)             (None, 2)                 1026      
                                                                 
=================================================================
Total params: 14,980,418
Trainable params: 14,979,394
Non-trainable params: 1,024
_________________________________________________________________
2023-06-14 04:17:44.431322: I tensorflow/core/common_runtime/executor.cc:1197] [/device:CPU:0] (DEBUG INFO) Executor start aborting (this does not indicate an error and you can ignore this message): INVALID_ARGUMENT: You must feed a value for placeholder tensor 'Placeholder/_0' with dtype int32
	 [[{{node Placeholder/_0}}]]
Epoch 1/1000
2023-06-14 04:20:25.257276: I tensorflow/compiler/xla/stream_executor/cuda/cuda_dnn.cc:424] Loaded cuDNN version 8600
2023-06-14 04:20:42.914067: I tensorflow/compiler/xla/stream_executor/cuda/cuda_blas.cc:637] TensorFloat-32 will be used for the matrix multiplication. This will only be logged once.
2023-06-14 04:20:44.636854: I tensorflow/core/common_runtime/executor.cc:1197] [/job:localhost/replica:0/task:0/device:GPU:0] (DEBUG INFO) Executor start aborting (this does not indicate an error and you can ignore this message): INVALID_ARGUMENT: logits and labels must be broadcastable: logits_size=[32,2] labels_size=[32,4]
	 [[{{node categorical_crossentropy/softmax_cross_entropy_with_logits}}]]
Traceback (most recent call last):
  File "/fs04/sk54/patrickli/automatic_visual_inference/scripts/single_plot_null_or_not_sim_only/single_plot_mixed_multiclass.py", line 65, in <module>
    fit_history = this_model.fit(x=train_set,
                  ^^^^^^^^^^^^^^^^^^^^^^^^^^^
  File "/scratch/sk54/wlii0039/miniconda/conda/envs/tf/lib/python3.11/site-packages/keras/utils/traceback_utils.py", line 70, in error_handler
    raise e.with_traceback(filtered_tb) from None
  File "/scratch/sk54/wlii0039/miniconda/conda/envs/tf/lib/python3.11/site-packages/tensorflow/python/eager/execute.py", line 52, in quick_execute
    tensors = pywrap_tfe.TFE_Py_Execute(ctx._handle, device_name, op_name,
  ^^^^^^^^^^^^^^^^^^^^^^^^^^^^^^^^^^^^^^^^^^^^^^^^^^^^^^^^^^^^^^^^^^^^^^^^
tensorflow.python.framework.errors_impl.InvalidArgumentError: Graph execution error:

Detected at node 'categorical_crossentropy/softmax_cross_entropy_with_logits' defined at (most recent call last):
    File "/fs04/sk54/patrickli/automatic_visual_inference/scripts/single_plot_null_or_not_sim_only/single_plot_mixed_multiclass.py", line 65, in <module>
      fit_history = this_model.fit(x=train_set,
    File "/scratch/sk54/wlii0039/miniconda/conda/envs/tf/lib/python3.11/site-packages/keras/utils/traceback_utils.py", line 65, in error_handler
      return fn(*args, **kwargs)
    File "/scratch/sk54/wlii0039/miniconda/conda/envs/tf/lib/python3.11/site-packages/keras/engine/training.py", line 1685, in fit
      tmp_logs = self.train_function(iterator)
    File "/scratch/sk54/wlii0039/miniconda/conda/envs/tf/lib/python3.11/site-packages/keras/engine/training.py", line 1284, in train_function
      return step_function(self, iterator)
    File "/scratch/sk54/wlii0039/miniconda/conda/envs/tf/lib/python3.11/site-packages/keras/engine/training.py", line 1268, in step_function
      outputs = model.distribute_strategy.run(run_step, args=(data,))
    File "/scratch/sk54/wlii0039/miniconda/conda/envs/tf/lib/python3.11/site-packages/keras/engine/training.py", line 1249, in run_step
      outputs = model.train_step(data)
    File "/scratch/sk54/wlii0039/miniconda/conda/envs/tf/lib/python3.11/site-packages/keras/engine/training.py", line 1051, in train_step
      loss = self.compute_loss(x, y, y_pred, sample_weight)
    File "/scratch/sk54/wlii0039/miniconda/conda/envs/tf/lib/python3.11/site-packages/keras/engine/training.py", line 1109, in compute_loss
      return self.compiled_loss(
    File "/scratch/sk54/wlii0039/miniconda/conda/envs/tf/lib/python3.11/site-packages/keras/engine/compile_utils.py", line 265, in __call__
      loss_value = loss_obj(y_t, y_p, sample_weight=sw)
    File "/scratch/sk54/wlii0039/miniconda/conda/envs/tf/lib/python3.11/site-packages/keras/losses.py", line 142, in __call__
      losses = call_fn(y_true, y_pred)
    File "/scratch/sk54/wlii0039/miniconda/conda/envs/tf/lib/python3.11/site-packages/keras/losses.py", line 268, in call
      return ag_fn(y_true, y_pred, **self._fn_kwargs)
    File "/scratch/sk54/wlii0039/miniconda/conda/envs/tf/lib/python3.11/site-packages/keras/losses.py", line 1984, in categorical_crossentropy
      return backend.categorical_crossentropy(
    File "/scratch/sk54/wlii0039/miniconda/conda/envs/tf/lib/python3.11/site-packages/keras/backend.py", line 5565, in categorical_crossentropy
      return tf.nn.softmax_cross_entropy_with_logits(
Node: 'categorical_crossentropy/softmax_cross_entropy_with_logits'
logits and labels must be broadcastable: logits_size=[32,2] labels_size=[32,4]
	 [[{{node categorical_crossentropy/softmax_cross_entropy_with_logits}}]] [Op:__inference_train_function_2468]
2023-06-14 04:20:45.755394: I tensorflow/core/common_runtime/executor.cc:1197] [/job:localhost/replica:0/task:0/device:CPU:0] (DEBUG INFO) Executor start aborting (this does not indicate an error and you can ignore this message): FAILED_PRECONDITION: Python interpreter state is not initialized. The process may be terminated.
	 [[{{node PyFunc}}]]
2023-06-14 04:20:45.755546: W tensorflow/core/kernels/data/generator_dataset_op.cc:108] Error occurred when finalizing GeneratorDataset iterator: FAILED_PRECONDITION: Python interpreter state is not initialized. The process may be terminated.
	 [[{{node PyFunc}}]]
